<! --   Basic xml file for manipulator   --> 

<mujoco model="manipulator">
  
  
<! --   Example right now...   -->   
  <body name="link0" pos="1.09 0.30 0.72">
        <geom name="bb" type="mesh" mesh="link_base" material="robot0:base_mat" rgba="1 1 1 1"/>
        <body name="link1" pos="0 0 0.267">
            <inertial pos="-0.0042142 0.02821 -0.0087788" quat="0.917781 -0.277115 0.0606681 0.277858" mass="0.42603" diaginertia="0.00144551 0.00137757 0.000823511" />
            <joint name="joint1" pos="0 0 0" axis="0 0 1" limited="true" range="-6.28319 6.28319" damping="10" frictionloss="1" />
            <geom name="j1" type="mesh" mesh="link1" material="robot0:arm_mat" rgba="1 1 1 1"/>
            <body name="link2" pos="0 0 0" quat="0.707105 -0.707108 0 0">
                <inertial pos="-3.3178e-05 -0.12849 0.026337" quat="0.447793 0.894132 -0.00224061 0.00218314" mass="0.56095" diaginertia="0.00319151 0.00311598 0.000980804" />
                <joint name="joint2" pos="0 0 0" axis="0 0 1" limited="true" range="-2.059 2.0944" damping="10" frictionloss="1" />
                <geom name="j2"  type="mesh"  mesh="link2" material="robot0:head_mat" rgba="1 1 1 1"/>
              
              
      </body>
    </body>
  </body>
</mujoco>

